Workbook

Sheet NCBI_SNP_EFEMP1
A1: NCBI Chromosome | B1: NCBI Position | C1: NCBI RS | D1: NCBI Reference Allele | E1: NCBI Alternative Allele
A2: 2 | B2: 55865969 | C2: rs1429945841 | D2: A | E2: G
A3: 2 | B3: 55865980 | C3: rs548260378 | D3: G | E3: A
A4: 2 | B4: 55865985 | C4: rs886056188 | D4: T | E4: G
A5: 2 | B5: 55865988 | C5: rs1197839931 | D5: A | E5: G
A6: 2 | B6: 55865996 | C6: rs568443337 | D6: T | E6: C
A7: 2 | B7: 55866007 | C7: rs1443740513 | D7: A | E7: G,T
A8: 2 | B8: 55866008 | C8: rs147551451 | D8: T | E8: C
A9: 2 | B9: 55866010 | C9: rs112334283 | D9: C | E9: T
A10: 2 | B10: 55866011 | C10: rs142276628 | D10: A | E10: G
A11: 2 | B11: 55866019 | C11: rs1224828836 | D11: A | E11: T
A12: 2 | B12: 55866029 | C12: rs1228344933 | D12: C | E12: T
A13: 2 | B13: 55866034 | C13: rs1284454126 | D13: T | E13: G
... A12517: 2 | B12517: 55924136 | C12517: rs987802851 | D12517: A | E12517: G

Sheet GWAS_CATALOG_EFEMP1
A1: PUBMEDID | B1: DISEASE/TRAIT | C1: GWAS Position | D1: GWAS Reported Gene(s) | E1: GWAS Mapped Gene | F1: GWAS RS/SNP | G1: GWAS Context | H1: GWAS Risk Allele Freq | I1: GWAS P-value | J1: GWAS Pvalue Mlog" | K1: GWAS Mapped Trait"
A2: 30578418 | B2: Pulse pressure | C2: 55875609 | D2: EFEMP1 | E2: EFEMP1 | F2: rs11899888-G | G2: intron_variant | H2: 0.8602 | I2: 1e-12 | J2: 12 | K2: pulse pressure measurement
A3: 31562340 | B3: Height | C3: 55869757 | D3: EFEMP1 | E3: EFEMP1 | F3: rs3791679-? | G3: intron_variant | H3: NR | I3: 4e-82 | J3: 81.39794 | K3: body height
A4: 32231278 | B4: Refractive error | C4: 55868231 | D4: ASB3, CHAC2, ERLEC1, GPR75, PSME4, ACYP2, SPTBN1, EML6, CCDC88A, CCDC104, SMEK2, PNPT1, EFEMP1 | E4: EFEMP1 | F4: rs9309272-? | G4: intron_variant | H4: NR | I4: 3e-34 | J4: 33.522879 | K4: Abnormality of refraction
A5: 32352494 | B5: Spherical equivalent | C5: 55907964 | D5: NR | E5: EFEMP1 | F5: rs78857879-G | G5: intron_variant | H5: NR | I5: 2e-15 | J5: 14.69897 | K5: refractive error
A6: 32358547 | B6: White matter hyperintensities | C6: 55900956 | D6: EFEMP1 | E6: EFEMP1 | F6: rs7596872-A | G6: intron_variant | H6: NR | I6: 2e-20 | J6: 19.69897 | K6: white matter hyperintensity measurement
A7: 30804560 | B7: Lung function (FVC) | C7: 55869757 | D7: EFEMP1 | E7: EFEMP1 | F7: rs3791679-A | G7: intron_variant | H7: 0.7714 | I7: 7e-35 | J7: 34.154902 | K7: vital capacity
A8: 32184442 | B8: Pelvic organ prolapse | C8: 55884174 | D8: EFEMP1 | E8: EFEMP1 | F8: rs3791675-C | G8: intron_variant | H8: 0.7893 | I8: 3e-11 | J8: 10.522879 | K8: pelvic organ prolapse
A9: 30804560 | B9: FEV1 | C9: 55869757 | D9: EFEMP1 | E9: EFEMP1 | F9: rs3791679-A | G9: intron_variant | H9: 0.7714 | I9: 3e-13 | J9: 12.522879 | K9: forced expiratory volume
A10: 31669095 | B10: Waist circumference adjusted for body mass index | C10: 55889288 | D10: NR | E10: EFEMP1 | F10: rs114866397-? | G10: intron_variant | H10: NR | I10: 6e-14 | J10: 13.221849 | K10: BMI-adjusted waist circumference
A11: 31669095 | B11: Waist circumference adjusted for body mass index | C11: 55868231 | D11: NR | E11: EFEMP1 | F11: rs9309272-? | G11: intron_variant | H11: NR | I11: 7e-33 | J11: 32.154902 | K11: BMI-adjusted waist circumference
A12: 31669095 | B12: Waist circumference adjusted for body mass index | C12: 55888699 | D12: NR | E12: EFEMP1 | F12: rs11125609-? | G12: intron_variant | H12: NR | I12: 9e-15 | J12: 14.045757 | K12: BMI-adjusted waist circumference
A13: 31669095 | B13: Waist circumference adjusted for body mass index | C13: 55907077 | D13: NR | E13: EFEMP1 | F13: rs56361700-? | G13: intron_variant | H13: NR | I13: 7e-10 | J13: 9.154902 | K13: BMI-adjusted waist circumference
... A60: 30664634 | B60: Body fat distribution (trunk fat ratio) | C60: 55869757 | D60: EFEMP1 | E60: EFEMP1 | F60: rs3791679-G | G60: intron_variant | H60: 0.227809 | I60: 2e-38 | J60: 37.69897 | K60: body fat distribution
A61: 30595370 | B61: Lung function (FEV1/FVC) | C61: 55885305 | E61: EFEMP1 | F61: rs1367228-? | G61: intron_variant | H61: NR | I61: 5e-24 | J61: 23.30103 | K61: FEV/FVC ratio
A62: 30595370 | B62: Lung function (FVC) | C62: 55869757 | E62: EFEMP1 | F62: rs3791679-? | G62: intron_variant | H62: NR | I62: 3e-35 | J62: 34.522879 | K62: vital capacity
A63: 25673412 | B63: Hip circumference adjusted for BMI | C63: 55869757 | D63: EFEMP1 | E63: EFEMP1 | F63: rs3791679-A | G63: intron_variant | H63: 0.7597 | I63: 1e-20 | J63: 20 | K63: BMI-adjusted hip circumference
A64: 25631615 | B64: Optic cup area | C64: 55881198 | D64: EFEMP1 | E64: EFEMP1 | F64: rs1346786-T | G64: intron_variant | H64: 0.31 | I64: 4e-08 | J64: 7.39794 | K64: optic cup area measurement
A65: 25631615 | B65: Optic cup area | C65: 55881198 | D65: EFEMP1 | E65: EFEMP1 | F65: rs1346786-T | G65: intron_variant | H65: 0.31 | I65: 8e-07 | J65: 6.09691 | K65: optic cup area measurement
A66: 24929828 | B66: Lung function (forced vital capacity) | C66: 55893718 | D66: EFEMP1 | E66: EFEMP1 | F66: rs1430193-T | G66: intron_variant | H66: 0.37 | I66: 2e-12 | J66: 11.69897 | K66: vital capacity
A67: 32517579 | B67: Periventricular white matter hyperintensities | C67: 55900956 | D67: EFEMP1 | E67: EFEMP1 | F67: rs7596872-A | G67: intron_variant | H67: 0.0975 | I67: 9e-11 | J67: 10.045757 | K67: white matter hyperintensity measurement
A68: 31217584 | B68: Height | C68: 55884174 | D68: NR | E68: EFEMP1 | F68: rs3791675-? | G68: intron_variant | H68: NR | I68: 1e-19 | J68: 19 | K68: body height
A69: 31217584 | B69: Height | C69: 55869757 | D69: NR | E69: EFEMP1 | F69: rs3791679-? | G69: intron_variant | H69: NR | I69: 2e-19 | J69: 18.69897 | K69: body height
A70: 34382107 | B70: Inguinal hernia | C70: 55875609 | E70: EFEMP1 | F70: rs11899888-G | G70: intron_variant | H70: 0.15 | I70: 1e-25 | J70: 25 | K70: Inguinal hernia
A71: 34382107 | B71: Inguinal hernia | C71: 55879793 | E71: EFEMP1 | F71: rs59985551-C | G71: intron_variant | H71: 0.77 | I71: 2e-45 | J71: 44.69897 | K71: Inguinal hernia
A72: 34382107 | B72: Inguinal hernia | C72: 55881198 | E72: EFEMP1 | F72: rs1346786-C | G72: intron_variant | H72: 0.71 | I72: 1e-41 | J72: 41 | K72: Inguinal hernia
A73: 34382107 | B73: Inguinal hernia | C73: 55884174 | E73: EFEMP1 | F73: rs3791675-C | G73: intron_variant | H73: 0.76 | I73: 3e-45 | J73: 44.522879 | K73: Inguinal hernia
A74: 34382107 | B74: Inguinal hernia | C74: 55885305 | E74: EFEMP1 | F74: rs1367228-C | G74: intron_variant | H74: 0.57 | I74: 3e-32 | J74: 31.522879 | K74: Inguinal hernia
A75: 34382107 | B75: Inguinal hernia | C75: 55890911 | E75: EFEMP1 | F75: rs10865291-G | G75: intron_variant | H75: 0.66 | I75: 6e-26 | J75: 25.221849 | K75: Inguinal hernia
A76: 34382107 | B76: Inguinal hernia | C76: 55891970 | E76: EFEMP1 | F76: rs6761893-A | G76: intron_variant | H76: 0.65 | I76: 1e-26 | J76: 26 | K76: Inguinal hernia
A77: 34382107 | B77: Inguinal hernia | C77: 55892522 | E77: EFEMP1 | F77: rs727878-C | G77: intron_variant | H77: 0.66 | I77: 3e-26 | J77: 25.522879 | K77: Inguinal hernia
A78: 34382107 | B78: Inguinal hernia | C78: 55892832 | E78: EFEMP1 | F78: rs2868431-G | G78: intron_variant | H78: 0.65 | I78: 9e-27 | J78: 26.045757 | K78: Inguinal hernia
A79: 34382107 | B79: Inguinal hernia | C79: 55893102 | E79: EFEMP1 | F79: rs6708689-A | G79: intron_variant | H79: 0.66 | I79: 2e-26 | J79: 25.69897 | K79: Inguinal hernia
A80: 34382107 | B80: Inguinal hernia | C80: 55893718 | E80: EFEMP1 | F80: rs1430193-A | G80: intron_variant | H80: 0.65 | I80: 2e-26 | J80: 25.69897 | K80: Inguinal hernia
A81: 34382107 | B81: Inguinal hernia | C81: 55894185 | E81: EFEMP1 | F81: rs1430194-A | G81: intron_variant | H81: 0.65 | I81: 1e-26 | J81: 26 | K81: Inguinal hernia
... A104: 34382107 | B104: Inguinal hernia | C104: 55923729 | E104: EFEMP1 | F104: rs3762515-T | G104: 5_prime_UTR_variant | H104: 0.09 | I104: 8e-14 | J104: 13.09691 | K104: Inguinal hernia
A105: 34021172 | B105: Waist circumference adjusted for body mass index | C105: 55879793 | D105: EFEMP1 | E105: EFEMP1 | F105: rs59985551-T | G105: intron_variant | H105: NR | I105: 1e-35 | J105: 35 | K105: BMI-adjusted waist circumference
A106: 34021172 | B106: Waist circumference adjusted for body mass index | C106: 55885305 | D106: EFEMP1 | E106: EFEMP1 | F106: rs1367228-A | G106: intron_variant | H106: NR | I106: 4e-12 | J106: 11.39794 | K106: BMI-adjusted waist circumference
A107: 34021172 | B107: Waist circumference adjusted for body mass index | C107: 55868859 | D107: EFEMP1 | E107: EFEMP1 | F107: rs17278665-G | G107: intron_variant | H107: NR | I107: 2e-24 | J107: 23.69897 | K107: BMI-adjusted waist circumference
A108: 34021172 | B108: Waist circumference adjusted for body mass index | C108: 55894434 | D108: EFEMP1 | E108: EFEMP1 | F108: rs779074208-T | G108: intron_variant | H108: NR | I108: 4e-14 | J108: 13.39794 | K108: BMI-adjusted waist circumference
...

Sheet GTEx INPUT
A1: PUBMEDID | B1: DISEASE/TRAIT | C1: GWAS Position | D1: GWAS Reported Gene(s) | E1: GWAS Mapped Gene | F1: GWAS RS/SNP | G1: GWAS Context | H1: GWAS Risk Allele Freq | I1: GWAS P-value | J1: GWAS Pvalue Mlog" | K1: GWAS Mapped Trait | L1: NCBI Chromosome | M1: NCBI Position | N1: NCBI RS | O1: NCBI Reference Allele | P1: NCBI Alternative Allele | Q1: RS isolated | R1: GWAS SNP Isolated | S1: GTEx Format | T1: Duplicate filtering | U1: Ref=Alt filtering
L2: 2 | M2: 55865969 | N2: rs1429945841 | O2: A | P2: G | Q2: =LEFT(F2, FIND("-", F2) - 1) -> #VALUE! | R2: =MID(F2, FIND("-", F2) + 1, 1) -> #VALUE! | S2: ="ENSG00000115380.19,chr2_" & 'GTEx INPUT'!$M2 & "_" &'GTEx INPUT'!$O2&"_"&'GTEx INPUT'!$R2&"_b38" -> #VALUE! | T2: =IF(COUNTIF($S:$S, S2) = 1, "Unique", IF(COUNTIF($S$2:S2, S2) = 1, "Duplicate representer", "Duplicate")) -> Duplicate representer | U2: =IF(O2 <> R2, "Different", "Same") -> #VALUE!
L3: 2 | M3: 55865980 | N3: rs548260378 | O3: G | P3: A | Q3: =LEFT(F3, FIND("-", F3) - 1) -> #VALUE! | R3: =MID(F3, FIND("-", F3) + 1, 1) -> #VALUE! | S3: ="ENSG00000115380.19,chr2_" & 'GTEx INPUT'!$M3 & "_" &'GTEx INPUT'!$O3&"_"&'GTEx INPUT'!$R3&"_b38" -> #VALUE! | T3: =IF(COUNTIF($S:$S, S3) = 1, "Unique", IF(COUNTIF($S$2:S3, S3) = 1, "Duplicate representer", "Duplicate")) -> Duplicate | U3: =IF(O3 <> R3, "Different", "Same") -> #VALUE!
A4: 32231278 | B4: Refractive error | C4: 55868231 | D4: ASB3, CHAC2, ERLEC1, GPR75, PSME4, ACYP2, SPTBN1, EML6, CCDC88A, CCDC104, SMEK2, PNPT1, EFEMP1 | E4: EFEMP1 | F4: rs9309272-? | G4: intron_variant | H4: NR | I4: 3e-34 | J4: 33.522879 | K4: Abnormality of refraction | L4: 2 | M4: 55868231 | N4: rs9309272 | O4: G | P4: T | Q4: =LEFT(F4, FIND("-", F4) - 1) -> rs9309272 | R4: =MID(F4, FIND("-", F4) + 1, 1) -> ? | S4: ="ENSG00000115380.19,chr2_" & 'GTEx INPUT'!$M4 & "_" &'GTEx INPUT'!$O4&"_"&'GTEx INPUT'!$R4&"_b38" -> ENSG00000115380.19,chr2_55868231_G_?_b38 | T4: =IF(COUNTIF($S:$S, S4) = 1, "Unique", IF(COUNTIF($S$2:S4, S4) = 1, "Duplicate representer", "Duplicate")) -> Duplicate representer | U4: =IF(O4 <> R4, "Different", "Same") -> Different
A5: 31669095 | B5: Waist circumference adjusted for body mass index | C5: 55868231 | D5: NR | E5: EFEMP1 | F5: rs9309272-? | G5: intron_variant | H5: NR | I5: 7e-33 | J5: 32.154902 | K5: BMI-adjusted waist circumference | L5: 2 | M5: 55868231 | N5: rs9309272 | O5: G | P5: T | Q5: =LEFT(F5, FIND("-", F5) - 1) -> rs9309272 | R5: =MID(F5, FIND("-", F5) + 1, 1) -> ? | S5: ="ENSG00000115380.19,chr2_" & 'GTEx INPUT'!$M5 & "_" &'GTEx INPUT'!$O5&"_"&'GTEx INPUT'!$R5&"_b38" -> ENSG00000115380.19,chr2_55868231_G_?_b38 | T5: =IF(COUNTIF($S:$S, S5) = 1, "Unique", IF(COUNTIF($S$2:S5, S5) = 1, "Duplicate representer", "Duplicate")) -> Duplicate | U5: =IF(O5 <> R5, "Different", "Same") -> Different
A6: 34382107 | B6: Inguinal hernia | C6: 55868231 | E6: EFEMP1 | F6: rs9309272-T | G6: intron_variant | H6: 0.13 | I6: 7e-24 | J6: 23.154902 | K6: Inguinal hernia | L6: 2 | M6: 55868231 | N6: rs9309272 | O6: G | P6: T | Q6: =LEFT(F6, FIND("-", F6) - 1) -> rs9309272 | R6: =MID(F6, FIND("-", F6) + 1, 1) -> T | S6: ="ENSG00000115380.19,chr2_" & 'GTEx INPUT'!$M6 & "_" &'GTEx INPUT'!$O6&"_"&'GTEx INPUT'!$R6&"_b38" -> ENSG00000115380.19,chr2_55868231_G_T_b38 | T6: =IF(COUNTIF($S:$S, S6) = 1, "Unique", IF(COUNTIF($S$2:S6, S6) = 1, "Duplicate representer", "Duplicate")) -> Unique | U6: =IF(O6 <> R6, "Different", "Same") -> Different
L7: 2 | M7: 55865985 | N7: rs886056188 | O7: T | P7: G | Q7: =LEFT(F7, FIND("-", F7) - 1) -> #VALUE! | R7: =MID(F7, FIND("-", F7) + 1, 1) -> #VALUE! | S7: ="ENSG00000115380.19,chr2_" & 'GTEx INPUT'!$M7 & "_" &'GTEx INPUT'!$O7&"_"&'GTEx INPUT'!$R7&"_b38" -> #VALUE! | T7: =IF(COUNTIF($S:$S, S7) = 1, "Unique", IF(COUNTIF($S$2:S7, S7) = 1, "Duplicate representer", "Duplicate")) -> Duplicate | U7: =IF(O7 <> R7, "Different", "Same") -> #VALUE!
L8: 2 | M8: 55865988 | N8: rs1197839931 | O8: A | P8: G | Q8: =LEFT(F8, FIND("-", F8) - 1) -> #VALUE! | R8: =MID(F8, FIND("-", F8) + 1, 1) -> #VALUE! | S8: ="ENSG00000115380.19,chr2_" & 'GTEx INPUT'!$M8 & "_" &'GTEx INPUT'!$O8&"_"&'GTEx INPUT'!$R8&"_b38" -> #VALUE! | T8: =IF(COUNTIF($S:$S, S8) = 1, "Unique", IF(COUNTIF($S$2:S8, S8) = 1, "Duplicate representer", "Duplicate")) -> Duplicate | U8: =IF(O8 <> R8, "Different", "Same") -> #VALUE!
L9: 2 | M9: 55865996 | N9: rs568443337 | O9: T | P9: C | Q9: =LEFT(F9, FIND("-", F9) - 1) -> #VALUE! | R9: =MID(F9, FIND("-", F9) + 1, 1) -> #VALUE! | S9: ="ENSG00000115380.19,chr2_" & 'GTEx INPUT'!$M9 & "_" &'GTEx INPUT'!$O9&"_"&'GTEx INPUT'!$R9&"_b38" -> #VALUE! | T9: =IF(COUNTIF($S:$S, S9) = 1, "Unique", IF(COUNTIF($S$2:S9, S9) = 1, "Duplicate representer", "Duplicate")) -> Duplicate | U9: =IF(O9 <> R9, "Different", "Same") -> #VALUE!
L10: 2 | M10: 55866007 | N10: rs1443740513 | O10: A | P10: G,T | Q10: =LEFT(F10, FIND("-", F10) - 1) -> #VALUE! | R10: =MID(F10, FIND("-", F10) + 1, 1) -> #VALUE! | S10: ="ENSG00000115380.19,chr2_" & 'GTEx INPUT'!$M10 & "_" &'GTEx INPUT'!$O10&"_"&'GTEx INPUT'!$R10&"_b38" -> #VALUE! | T10: =IF(COUNTIF($S:$S, S10) = 1, "Unique", IF(COUNTIF($S$2:S10, S10) = 1, "Duplicate representer", "Duplicate")) -> Duplicate | U10: =IF(O10 <> R10, "Different", "Same") -> #VALUE!
L11: 2 | M11: 55866008 | N11: rs147551451 | O11: T | P11: C | Q11: =LEFT(F11, FIND("-", F11) - 1) -> #VALUE! | R11: =MID(F11, FIND("-", F11) + 1, 1) -> #VALUE! | S11: ="ENSG00000115380.19,chr2_" & 'GTEx INPUT'!$M11 & "_" &'GTEx INPUT'!$O11&"_"&'GTEx INPUT'!$R11&"_b38" -> #VALUE! | T11: =IF(COUNTIF($S:$S, S11) = 1, "Unique", IF(COUNTIF($S$2:S11, S11) = 1, "Duplicate representer", "Duplicate")) -> Duplicate | U11: =IF(O11 <> R11, "Different", "Same") -> #VALUE!
L12: 2 | M12: 55866010 | N12: rs112334283 | O12: C | P12: T | Q12: =LEFT(F12, FIND("-", F12) - 1) -> #VALUE! | R12: =MID(F12, FIND("-", F12) + 1, 1) -> #VALUE! | S12: ="ENSG00000115380.19,chr2_" & 'GTEx INPUT'!$M12 & "_" &'GTEx INPUT'!$O12&"_"&'GTEx INPUT'!$R12&"_b38" -> #VALUE! | T12: =IF(COUNTIF($S:$S, S12) = 1, "Unique", IF(COUNTIF($S$2:S12, S12) = 1, "Duplicate representer", "Duplicate")) -> Duplicate | U12: =IF(O12 <> R12, "Different", "Same") -> #VALUE!
L13: 2 | M13: 55866011 | N13: rs142276628 | O13: A | P13: G | Q13: =LEFT(F13, FIND("-", F13) - 1) -> #VALUE! | R13: =MID(F13, FIND("-", F13) + 1, 1) -> #VALUE! | S13: ="ENSG00000115380.19,chr2_" & 'GTEx INPUT'!$M13 & "_" &'GTEx INPUT'!$O13&"_"&'GTEx INPUT'!$R13&"_b38" -> #VALUE! | T13: =IF(COUNTIF($S:$S, S13) = 1, "Unique", IF(COUNTIF($S$2:S13, S13) = 1, "Duplicate representer", "Duplicate")) -> Duplicate | U13: =IF(O13 <> R13, "Different", "Same") -> #VALUE!
L14: 2 | M14: 55866019 | N14: rs1224828836 | O14: A | P14: T | Q14: =LEFT(F14, FIND("-", F14) - 1) -> #VALUE! | R14: =MID(F14, FIND("-", F14) + 1, 1) -> #VALUE! | S14: ="ENSG00000115380.19,chr2_" & 'GTEx INPUT'!$M14 & "_" &'GTEx INPUT'!$O14&"_"&'GTEx INPUT'!$R14&"_b38" -> #VALUE! | T14: =IF(COUNTIF($S:$S, S14) = 1, "Unique", IF(COUNTIF($S$2:S14, S14) = 1, "Duplicate representer", "Duplicate")) -> Duplicate | U14: =IF(O14 <> R14, "Different", "Same") -> #VALUE!
L15: 2 | M15: 55866029 | N15: rs1228344933 | O15: C | P15: T | Q15: =LEFT(F15, FIND("-", F15) - 1) -> #VALUE! | R15: =MID(F15, FIND("-", F15) + 1, 1) -> #VALUE! | S15: ="ENSG00000115380.19,chr2_" & 'GTEx INPUT'!$M15 & "_" &'GTEx INPUT'!$O15&"_"&'GTEx INPUT'!$R15&"_b38" -> #VALUE! | T15: =IF(COUNTIF($S:$S, S15) = 1, "Unique", IF(COUNTIF($S$2:S15, S15) = 1, "Duplicate representer", "Duplicate")) -> Duplicate | U15: =IF(O15 <> R15, "Different", "Same") -> #VALUE!
L16: 2 | M16: 55866034 | N16: rs1284454126 | O16: T | P16: G | Q16: =LEFT(F16, FIND("-", F16) - 1) -> #VALUE! | R16: =MID(F16, FIND("-", F16) + 1, 1) -> #VALUE! | S16: ="ENSG00000115380.19,chr2_" & 'GTEx INPUT'!$M16 & "_" &'GTEx INPUT'!$O16&"_"&'GTEx INPUT'!$R16&"_b38" -> #VALUE! | T16: =IF(COUNTIF($S:$S, S16) = 1, "Unique", IF(COUNTIF($S$2:S16, S16) = 1, "Duplicate representer", "Duplicate")) -> Duplicate | U16: =IF(O16 <> R16, "Different", "Same") -> #VALUE!
L17: 2 | M17: 55866047 | N17: rs540075808 | O17: G | P17: A | Q17: =LEFT(F17, FIND("-", F17) - 1) -> #VALUE! | R17: =MID(F17, FIND("-", F17) + 1, 1) -> #VALUE! | S17: ="ENSG00000115380.19,chr2_" & 'GTEx INPUT'!$M17 & "_" &'GTEx INPUT'!$O17&"_"&'GTEx INPUT'!$R17&"_b38" -> #VALUE! | T17: =IF(COUNTIF($S:$S, S17) = 1, "Unique", IF(COUNTIF($S$2:S17, S17) = 1, "Duplicate representer", "Duplicate")) -> Duplicate | U17: =IF(O17 <> R17, "Different", "Same") -> #VALUE!
L18: 2 | M18: 55866049 | N18: rs1329703235 | O18: A | P18: G | Q18: =LEFT(F18, FIND("-", F18) - 1) -> #VALUE! | R18: =MID(F18, FIND("-", F18) + 1, 1) -> #VALUE! | S18: ="ENSG00000115380.19,chr2_" & 'GTEx INPUT'!$M18 & "_" &'GTEx INPUT'!$O18&"_"&'GTEx INPUT'!$R18&"_b38" -> #VALUE! | T18: =IF(COUNTIF($S:$S, S18) = 1, "Unique", IF(COUNTIF($S$2:S18, S18) = 1, "Duplicate representer", "Duplicate")) -> Duplicate | U18: =IF(O18 <> R18, "Different", "Same") -> #VALUE!
... L20: 2 | M20: 55866064 | N20: rs1392120006 | O20: G | P20: C | Q20: =LEFT(F20, FIND("-", F20) - 1) -> #VALUE! | R20: =MID(F20, FIND("-", F20) + 1, 1) -> #VALUE! | S20: ="ENSG00000115380.19,chr2_" & 'GTEx INPUT'!$M20 & "_" &'GTEx INPUT'!$O20&"_"&'GTEx INPUT'!$R20&"_b38" -> #VALUE! | T20: =IF(COUNTIF($S:$S, S20) = 1, "Unique", IF(COUNTIF($S$2:S20, S20) = 1, "Duplicate representer", "Duplicate")) -> Duplicate | U20: =IF(O20 <> R20, "Different", "Same") -> #VALUE!
A21: 34382107 | B21: Inguinal hernia | C21: 55866069 | E21: EFEMP1 | F21: rs1802575-C | G21: 3_prime_UTR_variant | H21: 0.13 | I21: 3e-24 | J21: 23.522879 | K21: Inguinal hernia | L21: 2 | M21: 55866069 | N21: rs1802575 | O21: G | P21: C | Q21: =LEFT(F21, FIND("-", F21) - 1) -> rs1802575 | R21: =MID(F21, FIND("-", F21) + 1, 1) -> C | S21: ="ENSG00000115380.19,chr2_" & 'GTEx INPUT'!$M21 & "_" &'GTEx INPUT'!$O21&"_"&'GTEx INPUT'!$R21&"_b38" -> ENSG00000115380.19,chr2_55866069_G_C_b38 | T21: =IF(COUNTIF($S:$S, S21) = 1, "Unique", IF(COUNTIF($S$2:S21, S21) = 1, "Duplicate representer", "Duplicate")) -> Duplicate representer | U21: =IF(O21 <> R21, "Different", "Same") -> Different
A22: 28928442 | B22: Childhood ear infection | C22: 55866069 | D22: EFEMP1 | E22: EFEMP1 | F22: rs1802575-G | G22: 3_prime_UTR_variant | H22: 0.87 | I22: 1e-10 | J22: 10 | K22: susceptibility to childhood ear infection measurement | L22: 2 | M22: 55866069 | N22: rs1802575 | O22: G | P22: C | Q22: =LEFT(F22, FIND("-", F22) - 1) -> rs1802575 | R22: =MID(F22, FIND("-", F22) + 1, 1) -> G | S22: ="ENSG00000115380.19,chr2_" & 'GTEx INPUT'!$M22 & "_" &'GTEx INPUT'!$O22&"_"&'GTEx INPUT'!$R22&"_b38" -> ENSG00000115380.19,chr2_55866069_G_G_b38 | T22: =IF(COUNTIF($S:$S, S22) = 1, "Unique", IF(COUNTIF($S$2:S22, S22) = 1, "Duplicate representer", "Duplicate")) -> Unique | U22: =IF(O22 <> R22, "Different", "Same") -> Same
A23: 27182965 | B23: Childhood ear infection | C23: 55866069 | D23: EFEMP1 | E23: EFEMP1 | F23: rs1802575-? | G23: 3_prime_UTR_variant | H23: NR | I23: 2e-10 | J23: 9.69897 | K23: susceptibility to childhood ear infection measurement | L23: 2 | M23: 55866069 | N23: rs1802575 | O23: G | P23: C | Q23: =LEFT(F23, FIND("-", F23) - 1) -> rs1802575 | R23: =MID(F23, FIND("-", F23) + 1, 1) -> ? | S23: ="ENSG00000115380.19,chr2_" & 'GTEx INPUT'!$M23 & "_" &'GTEx INPUT'!$O23&"_"&'GTEx INPUT'!$R23&"_b38" -> ENSG00000115380.19,chr2_55866069_G_?_b38 | T23: =IF(COUNTIF($S:$S, S23) = 1, "Unique", IF(COUNTIF($S$2:S23, S23) = 1, "Duplicate representer", "Duplicate")) -> Duplicate | U23: =IF(O23 <> R23, "Different", "Same") -> Different
A24: 30177863 | B24: Diverticular disease | C24: 55866069 | D24: EFEMP1 | E24: EFEMP1 | F24: rs1802575-C | G24: 3_prime_UTR_variant | H24: 0.132914713398429 | I24: 8e-16 | J24: 15.09691 | K24: diverticular disease | L24: 2 | M24: 55866069 | N24: rs1802575 | O24: G | P24: C | Q24: =LEFT(F24, FIND("-", F24) - 1) -> rs1802575 | R24: =MID(F24, FIND("-", F24) + 1, 1) -> C | S24: ="ENSG00000115380.19,chr2_" & 'GTEx INPUT'!$M24 & "_" &'GTEx INPUT'!$O24&"_"&'GTEx INPUT'!$R24&"_b38" -> ENSG00000115380.19,chr2_55866069_G_C_b38 | T24: =IF(COUNTIF($S:$S, S24) = 1, "Unique", IF(COUNTIF($S$2:S24, S24) = 1, "Duplicate representer", "Duplicate")) -> Duplicate | U24: =IF(O24 <> R24, "Different", "Same") -> Different
A25: 34021172 | B25: Waist circumference adjusted for body mass index | C25: 55866069 | D25: EFEMP1 | E25: EFEMP1 | F25: rs1802575-C | G25: 3_prime_UTR_variant | H25: NR | I25: 4e-08 | J25: 7.39794 | K25: BMI-adjusted waist circumference | L25: 2 | M25: 55866069 | N25: rs1802575 | O25: G | P25: C | Q25: =LEFT(F25, FIND("-", F25) - 1) -> rs1802575 | R25: =MID(F25, FIND("-", F25) + 1, 1) -> C | S25: ="ENSG00000115380.19,chr2_" & 'GTEx INPUT'!$M25 & "_" &'GTEx INPUT'!$O25&"_"&'GTEx INPUT'!$R25&"_b38" -> ENSG00000115380.19,chr2_55866069_G_C_b38 | T25: =IF(COUNTIF($S:$S, S25) = 1, "Unique", IF(COUNTIF($S$2:S25, S25) = 1, "Duplicate representer", "Duplicate")) -> Duplicate | U25: =IF(O25 <> R25, "Different", "Same") -> Different
A26: 38689001 | B26: Diastolic blood pressure | C26: 55866069 | E26: EFEMP1 | F26: rs1802575-C | G26: 3_prime_UTR_variant | H26: NR | I26: 5e-10 | J26: 9.30103 | K26: diastolic blood pressure | L26: 2 | M26: 55866069 | N26: rs1802575 | O26: G | P26: C | Q26: =LEFT(F26, FIND("-", F26) - 1) -> rs1802575 | R26: =MID(F26, FIND("-", F26) + 1, 1) -> C | S26: ="ENSG00000115380.19,chr2_" & 'GTEx INPUT'!$M26 & "_" &'GTEx INPUT'!$O26&"_"&'GTEx INPUT'!$R26&"_b38" -> ENSG00000115380.19,chr2_55866069_G_C_b38 | T26: =IF(COUNTIF($S:$S, S26) = 1, "Unique", IF(COUNTIF($S$2:S26, S26) = 1, "Duplicate representer", "Duplicate")) -> Duplicate | U26: =IF(O26 <> R26, "Different", "Same") -> Different
A27: 38689001 | B27: Pulse pressure | C27: 55866069 | E27: EFEMP1 | F27: rs1802575-C | G27: 3_prime_UTR_variant | H27: NR | I27: 6e-20 | J27: 19.221849 | K27: pulse pressure measurement | L27: 2 | M27: 55866069 | N27: rs1802575 | O27: G | P27: C | Q27: =LEFT(F27, FIND("-", F27) - 1) -> rs1802575 | R27: =MID(F27, FIND("-", F27) + 1, 1) -> C | S27: ="ENSG00000115380.19,chr2_" & 'GTEx INPUT'!$M27 & "_" &'GTEx INPUT'!$O27&"_"&'GTEx INPUT'!$R27&"_b38" -> ENSG00000115380.19,chr2_55866069_G_C_b38 | T27: =IF(COUNTIF($S:$S, S27) = 1, "Unique", IF(COUNTIF($S$2:S27, S27) = 1, "Duplicate representer", "Duplicate")) -> Duplicate | U27: =IF(O27 <> R27, "Different", "Same") -> Different
L28: 2 | M28: 55866074 | N28: rs1329350164 | O28: G | P28: C | Q28: =LEFT(F28, FIND("-", F28) - 1) -> #VALUE! | R28: =MID(F28, FIND("-", F28) + 1, 1) -> #VALUE! | S28: ="ENSG00000115380.19,chr2_" & 'GTEx INPUT'!$M28 & "_" &'GTEx INPUT'!$O28&"_"&'GTEx INPUT'!$R28&"_b38" -> #VALUE! | T28: =IF(COUNTIF($S:$S, S28) = 1, "Unique", IF(COUNTIF($S$2:S28, S28) = 1, "Duplicate representer", "Duplicate")) -> Duplicate | U28: =IF(O28 <> R28, "Different", "Same") -> #VALUE!
L29: 2 | M29: 55866075 | N29: rs955535015 | O29: G | P29: A | Q29: =LEFT(F29, FIND("-", F29) - 1) -> #VALUE! | R29: =MID(F29, FIND("-", F29) + 1, 1) -> #VALUE! | S29: ="ENSG00000115380.19,chr2_" & 'GTEx INPUT'!$M29 & "_" &'GTEx INPUT'!$O29&"_"&'GTEx INPUT'!$R29&"_b38" -> #VALUE! | T29: =IF(COUNTIF($S:$S, S29) = 1, "Unique", IF(COUNTIF($S$2:S29, S29) = 1, "Duplicate representer", "Duplicate")) -> Duplicate | U29: =IF(O29 <> R29, "Different", "Same") -> #VALUE!
L30: 2 | M30: 55866077 | N30: rs1278182683 | O30: G | P30: A | Q30: =LEFT(F30, FIND("-", F30) - 1) -> #VALUE! | R30: =MID(F30, FIND("-", F30) + 1, 1) -> #VALUE! | S30: ="ENSG00000115380.19,chr2_" & 'GTEx INPUT'!$M30 & "_" &'GTEx INPUT'!$O30&"_"&'GTEx INPUT'!$R30&"_b38" -> #VALUE! | T30: =IF(COUNTIF($S:$S, S30) = 1, "Unique", IF(COUNTIF($S$2:S30, S30) = 1, "Duplicate representer", "Duplicate")) -> Duplicate | U30: =IF(O30 <> R30, "Different", "Same") -> #VALUE!
L31: 2 | M31: 55866079 | N31: rs986958143 | O31: G | P31: A | Q31: =LEFT(F31, FIND("-", F31) - 1) -> #VALUE! | R31: =MID(F31, FIND("-", F31) + 1, 1) -> #VALUE! | S31: ="ENSG00000115380.19,chr2_" & 'GTEx INPUT'!$M31 & "_" &'GTEx INPUT'!$O31&"_"&'GTEx INPUT'!$R31&"_b38" -> #VALUE! | T31: =IF(COUNTIF($S:$S, S31) = 1, "Unique", IF(COUNTIF($S$2:S31, S31) = 1, "Duplicate representer", "Duplicate")) -> Duplicate | U31: =IF(O31 <> R31, "Different", "Same") -> #VALUE!
L32: 2 | M32: 55866080 | N32: rs185614902 | O32: T | P32: G | Q32: =LEFT(F32, FIND("-", F32) - 1) -> #VALUE! | R32: =MID(F32, FIND("-", F32) + 1, 1) -> #VALUE! | S32: ="ENSG00000115380.19,chr2_" & 'GTEx INPUT'!$M32 & "_" &'GTEx INPUT'!$O32&"_"&'GTEx INPUT'!$R32&"_b38" -> #VALUE! | T32: =IF(COUNTIF($S:$S, S32) = 1, "Unique", IF(COUNTIF($S$2:S32, S32) = 1, "Duplicate representer", "Duplicate")) -> Duplicate | U32: =IF(O32 <> R32, "Different", "Same") -> #VALUE!
L33: 2 | M33: 55866081 | N33: rs1477039941 | O33: A | P33: C | Q33: =LEFT(F33, FIND("-", F33) - 1) -> #VALUE! | R33: =MID(F33, FIND("-", F33) + 1, 1) -> #VALUE! | S33: ="ENSG00000115380.19,chr2_" & 'GTEx INPUT'!$M33 & "_" &'GTEx INPUT'!$O33&"_"&'GTEx INPUT'!$R33&"_b38" -> #VALUE! | T33: =IF(COUNTIF($S:$S, S33) = 1, "Unique", IF(COUNTIF($S$2:S33, S33) = 1, "Duplicate representer", "Duplicate")) -> Duplicate | U33: =IF(O33 <> R33, "Different", "Same") -> #VALUE!
L34: 2 | M34: 55866087 | N34: rs1365314951 | O34: C | P34: T | Q34: =LEFT(F34, FIND("-", F34) - 1) -> #VALUE! | R34: =MID(F34, FIND("-", F34) + 1, 1) -> #VALUE! | S34: ="ENSG00000115380.19,chr2_" & 'GTEx INPUT'!$M34 & "_" &'GTEx INPUT'!$O34&"_"&'GTEx INPUT'!$R34&"_b38" -> #VALUE! | T34: =IF(COUNTIF($S:$S, S34) = 1, "Unique", IF(COUNTIF($S$2:S34, S34) = 1, "Duplicate representer", "Duplicate")) -> Duplicate | U34: =IF(O34 <> R34, "Different", "Same") -> #VALUE!
L35: 2 | M35: 55866103 | N35: rs1184004413 | O35: C | P35: T | Q35: =LEFT(F35, FIND("-", F35) - 1) -> #VALUE! | R35: =MID(F35, FIND("-", F35) + 1, 1) -> #VALUE! | S35: ="ENSG00000115380.19,chr2_" & 'GTEx INPUT'!$M35 & "_" &'GTEx INPUT'!$O35&"_"&'GTEx INPUT'!$R35&"_b38" -> #VALUE! | T35: =IF(COUNTIF($S:$S, S35) = 1, "Unique", IF(COUNTIF($S$2:S35, S35) = 1, "Duplicate representer", "Duplicate")) -> Duplicate | U35: =IF(O35 <> R35, "Different", "Same") -> #VALUE!
L36: 2 | M36: 55866105 | N36: rs1438627009 | O36: C | P36: G | Q36: =LEFT(F36, FIND("-", F36) - 1) -> #VALUE! | R36: =MID(F36, FIND("-", F36) + 1, 1) -> #VALUE! | S36: ="ENSG00000115380.19,chr2_" & 'GTEx INPUT'!$M36 & "_" &'GTEx INPUT'!$O36&"_"&'GTEx INPUT'!$R36&"_b38" -> #VALUE! | T36: =IF(COUNTIF($S:$S, S36) = 1, "Unique", IF(COUNTIF($S$2:S36, S36) = 1, "Duplicate representer", "Duplicate")) -> Duplicate | U36: =IF(O36 <> R36, "Different", "Same") -> #VALUE!
L37: 2 | M37: 55866108 | N37: rs1235998805 | O37: G | P37: C | Q37: =LEFT(F37, FIND("-", F37) - 1) -> #VALUE! | R37: =MID(F37, FIND("-", F37) + 1, 1) -> #VALUE! | S37: ="ENSG00000115380.19,chr2_" & 'GTEx INPUT'!$M37 & "_" &'GTEx INPUT'!$O37&"_"&'GTEx INPUT'!$R37&"_b38" -> #VALUE! | T37: =IF(COUNTIF($S:$S, S37) = 1, "Unique", IF(COUNTIF($S$2:S37, S37) = 1, "Duplicate representer", "Duplicate")) -> Duplicate | U37: =IF(O37 <> R37, "Different", "Same") -> #VALUE!
L38: 2 | M38: 55866110 | N38: rs190519603 | O38: T | P38: C | Q38: =LEFT(F38, FIND("-", F38) - 1) -> #VALUE! | R38: =MID(F38, FIND("-", F38) + 1, 1) -> #VALUE! | S38: ="ENSG00000115380.19,chr2_" & 'GTEx INPUT'!$M38 & "_" &'GTEx INPUT'!$O38&"_"&'GTEx INPUT'!$R38&"_b38" -> #VALUE! | T38: =IF(COUNTIF($S:$S, S38) = 1, "Unique", IF(COUNTIF($S$2:S38, S38) = 1, "Duplicate representer", "Duplicate")) -> Duplicate | U38: =IF(O38 <> R38, "Different", "Same") -> #VALUE!
L39: 2 | M39: 55866111 | N39: rs77386452 | O39: G | P39: T | Q39: =LEFT(F39, FIND("-", F39) - 1) -> #VALUE! | R39: =MID(F39, FIND("-", F39) + 1, 1) -> #VALUE! | S39: ="ENSG00000115380.19,chr2_" & 'GTEx INPUT'!$M39 & "_" &'GTEx INPUT'!$O39&"_"&'GTEx INPUT'!$R39&"_b38" -> #VALUE! | T39: =IF(COUNTIF($S:$S, S39) = 1, "Unique", IF(COUNTIF($S$2:S39, S39) = 1, "Duplicate representer", "Duplicate")) -> Duplicate | U39: =IF(O39 <> R39, "Different", "Same") -> #VALUE!
... L55: 2 | M55: 55866198 | N55: rs941993096 | O55: T | P55: C | Q55: =LEFT(F55, FIND("-", F55) - 1) -> #VALUE! | R55: =MID(F55, FIND("-", F55) + 1, 1) -> #VALUE! | S55: ="ENSG00000115380.19,chr2_" & 'GTEx INPUT'!$M55 & "_" &'GTEx INPUT'!$O55&"_"&'GTEx INPUT'!$R55&"_b38" -> #VALUE! | T55: =IF(COUNTIF($S:$S, S55) = 1, "Unique", IF(COUNTIF($S$2:S55, S55) = 1, "Duplicate representer", "Duplicate")) -> Duplicate | U55: =IF(O55 <> R55, "Different", "Same") -> #VALUE!
A56: 29235454 | B56: Intraocular pressure | C56: 55867875 | D56: EFEMP1 | E56: EFEMP1 | F56: rs7426380-? | G56: intron_variant | H56: NR | I56: 2e-13 | J56: 12.69897 | K56: intraocular pressure measurement | L56: 2 | M56: 55867875 | N56: rs7426380 | O56: A | P56: G | Q56: =LEFT(F56, FIND("-", F56) - 1) -> rs7426380 | R56: =MID(F56, FIND("-", F56) + 1, 1) -> ? | S56: ="ENSG00000115380.19,chr2_" & 'GTEx INPUT'!$M56 & "_" &'GTEx INPUT'!$O56&"_"&'GTEx INPUT'!$R56&"_b38" -> ENSG00000115380.19,chr2_55867875_A_?_b38 | T56: =IF(COUNTIF($S:$S, S56) = 1, "Unique", IF(COUNTIF($S$2:S56, S56) = 1, "Duplicate representer", "Duplicate")) -> Duplicate representer | U56: =IF(O56 <> R56, "Different", "Same") -> Different
...
